Workbook

Sheet Übersicht
A1: Kerncurricula Hessen, Sek I (Haupt-, Real- und Gymnasialfassung) mit BNE
A2: Stand der Auswertung: 26.10.2026. Quelle: Hessisches Kultusministerium, Seite 'Sekundarstufe I – Kerncurricula'.
A4: Fach | B4: Inhaltsfelder | C4: Schwerpunkte | D4: Anknüpfungspunkte | E4: SDG-Vorschläge | F4: PDF Hauptschule | G4: PDF Realschule | H4: PDF Gymnasium
A5: Deutsch | B5: =COUNTIF(Inhaltsfelder!B:B,A5) | C5: =COUNTIF(Schwerpunkte!B:B,A5) | D5: =COUNTIF(Anknüpfungspunkte!B:B,A5) | E5: =COUNTIF('SDG-Vorschläge'!C:C,A5) | F5: PDF | G5: PDF | H5: PDF
A6: Moderne Fremdsprachen | B6: =COUNTIF(Inhaltsfelder!B:B,A6) | C6: =COUNTIF(Schwerpunkte!B:B,A6) | D6: =COUNTIF(Anknüpfungspunkte!B:B,A6) | E6: =COUNTIF('SDG-Vorschläge'!C:C,A6) | F6: PDF | G6: PDF | H6: PDF
A7: Kunst | B7: =COUNTIF(Inhaltsfelder!B:B,A7) | C7: =COUNTIF(Schwerpunkte!B:B,A7) | D7: =COUNTIF(Anknüpfungspunkte!B:B,A7) | E7: =COUNTIF('SDG-Vorschläge'!C:C,A7) | F7: PDF | G7: PDF | H7: PDF
A8: Musik | B8: =COUNTIF(Inhaltsfelder!B:B,A8) | C8: =COUNTIF(Schwerpunkte!B:B,A8) | D8: =COUNTIF(Anknüpfungspunkte!B:B,A8) | E8: =COUNTIF('SDG-Vorschläge'!C:C,A8) | F8: PDF | G8: PDF | H8: PDF
A9: Sport | B9: =COUNTIF(Inhaltsfelder!B:B,A9) | C9: =COUNTIF(Schwerpunkte!B:B,A9) | D9: =COUNTIF(Anknüpfungspunkte!B:B,A9) | E9: =COUNTIF('SDG-Vorschläge'!C:C,A9) | F9: PDF | G9: PDF | H9: PDF
A10: Mathematik | B10: =COUNTIF(Inhaltsfelder!B:B,A10) | C10: =COUNTIF(Schwerpunkte!B:B,A10) | D10: =COUNTIF(Anknüpfungspunkte!B:B,A10) | E10: =COUNTIF('SDG-Vorschläge'!C:C,A10) | F10: PDF | G10: PDF | H10: PDF
A11: Informatik | B11: =COUNTIF(Inhaltsfelder!B:B,A11) | C11: =COUNTIF(Schwerpunkte!B:B,A11) | D11: =COUNTIF(Anknüpfungspunkte!B:B,A11) | E11: =COUNTIF('SDG-Vorschläge'!C:C,A11) | H11: PDF
A12: Physik | B12: =COUNTIF(Inhaltsfelder!B:B,A12) | C12: =COUNTIF(Schwerpunkte!B:B,A12) | D12: =COUNTIF(Anknüpfungspunkte!B:B,A12) | E12: =COUNTIF('SDG-Vorschläge'!C:C,A12) | F12: PDF | G12: PDF | H12: PDF
A13: Chemie | B13: =COUNTIF(Inhaltsfelder!B:B,A13) | C13: =COUNTIF(Schwerpunkte!B:B,A13) | D13: =COUNTIF(Anknüpfungspunkte!B:B,A13) | E13: =COUNTIF('SDG-Vorschläge'!C:C,A13) | F13: PDF | G13: PDF | H13: PDF
A14: Biologie | B14: =COUNTIF(Inhaltsfelder!B:B,A14) | C14: =COUNTIF(Schwerpunkte!B:B,A14) | D14: =COUNTIF(Anknüpfungspunkte!B:B,A14) | E14: =COUNTIF('SDG-Vorschläge'!C:C,A14) | F14: PDF | G14: PDF | H14: PDF
A15: Erdkunde | B15: =COUNTIF(Inhaltsfelder!B:B,A15) | C15: =COUNTIF(Schwerpunkte!B:B,A15) | D15: =COUNTIF(Anknüpfungspunkte!B:B,A15) | E15: =COUNTIF('SDG-Vorschläge'!C:C,A15) | F15: PDF | G15: PDF | H15: PDF
A16: Geschichte | B16: =COUNTIF(Inhaltsfelder!B:B,A16) | C16: =COUNTIF(Schwerpunkte!B:B,A16) | D16: =COUNTIF(Anknüpfungspunkte!B:B,A16) | E16: =COUNTIF('SDG-Vorschläge'!C:C,A16) | F16: PDF | G16: PDF | H16: PDF
A17: Politik und Wirtschaft | B17: =COUNTIF(Inhaltsfelder!B:B,A17) | C17: =COUNTIF(Schwerpunkte!B:B,A17) | D17: =COUNTIF(Anknüpfungspunkte!B:B,A17) | E17: =COUNTIF('SDG-Vorschläge'!C:C,A17) | F17: PDF | G17: PDF | H17: PDF
A18: Arbeitslehre | B18: =COUNTIF(Inhaltsfelder!B:B,A18) | C18: =COUNTIF(Schwerpunkte!B:B,A18) | D18: =COUNTIF(Anknüpfungspunkte!B:B,A18) | E18: =COUNTIF('SDG-Vorschläge'!C:C,A18) | F18: PDF | G18: PDF
A19: Ethik | B19: =COUNTIF(Inhaltsfelder!B:B,A19) | C19: =COUNTIF(Schwerpunkte!B:B,A19) | D19: =COUNTIF(Anknüpfungspunkte!B:B,A19) | E19: =COUNTIF('SDG-Vorschläge'!C:C,A19) | F19: PDF | G19: PDF | H19: PDF
A20: Evangelische Religion | B20: =COUNTIF(Inhaltsfelder!B:B,A20) | C20: =COUNTIF(Schwerpunkte!B:B,A20) | D20: =COUNTIF(Anknüpfungspunkte!B:B,A20) | E20: =COUNTIF('SDG-Vorschläge'!C:C,A20) | F20: PDF | G20: PDF | H20: PDF
A21: Katholische Religion | B21: =COUNTIF(Inhaltsfelder!B:B,A21) | C21: =COUNTIF(Schwerpunkte!B:B,A21) | D21: =COUNTIF(Anknüpfungspunkte!B:B,A21) | E21: =COUNTIF('SDG-Vorschläge'!C:C,A21) | F21: PDF | G21: PDF | H21: PDF
A22: Summe | B22: =SUM(B5:B21) | C22: =SUM(C5:C21) | D22: =SUM(D5:D21) | E22: =SUM(E5:E21)
A24: Tabellenblätter
A25: Inhaltsfelder | B25: Alle Inhaltsfelder je Fach mit Einordnung und Seitenangabe je KC-Fassung (leer = in dieser Fassung nicht vorhanden)
A26: Schwerpunkte | B26: Inhaltliche Schwerpunkte je Inhaltsfeld und Stufe, bisher nur Pilotfächer in der Gymnasialfassung
A27: Kompetenzbereiche | B27: Fachliche Kompetenzbereiche und Teilbereiche
A28: Querbezüge belegt | B28: Fächerübergreifende Bezüge, die ausdrücklich im KC stehen
A29: Anknüpfungspunkte | B29: Themenvorschläge über gemeinsame Stichworte, zu prüfen
A30: BNE Belege | B30: Stellen, an denen das KC selbst Nachhaltigkeit nennt (BNE ist Aufgabengebiet nach § 6 Abs. 4 HSchG)
A31: SDG-Vorschläge | B31: Zuordnung von Inhaltsfeldern zu den 17 Nachhaltigkeitszielen, zu prüfen
A32: Hinweise und Lücken | B32: Was fehlt oder abweicht

Sheet Inhaltsfelder
A1: ID | B1: Fach | C1: Einordnung im KC | D1: Inhaltsfeld | E1: Seite HS (Kap. 6) | F1: Seite RS (Kap. 6) | G1: Seite GY (Kap. 6) | H1: Hinweis
A2: IF-001 | B2: Biologie | C2: Basiskonzept Struktur und Funktion | D2: Biologische Strukturen und ihre Funktion | E2: S. 28 | F2: S. 28 | G2: S. 28
A3: IF-002 | B3: Biologie | C3: Basiskonzept Struktur und Funktion | D3: Informationsfluss im Organismus und zwischen Organismen | E3: S. 28 | F3: S. 28 | G3: S. 28 f.
A4: IF-003 | B4: Biologie | C4: Basiskonzept System | D4: Funktionsteilung im Organismus | E4: S. 29 | F4: S. 29 | G4: S. 29
A5: IF-004 | B5: Biologie | C5: Basiskonzept System | D5: Wechselwirkungen in Ökosystemen | E5: S. 29 | F5: S. 30 | G5: S. 29 f.
A6: IF-005 | B6: Biologie | C6: Basiskonzept System | D6: Stoffwechsel und Regelmechanismen | E6: S. 30 | F6: S. 30 | G6: S. 30
A7: IF-006 | B7: Biologie | C7: Basiskonzept Entwicklung | D7: Fortpflanzung und Entwicklung | E7: S. 31 | F7: S. 31 | G7: S. 31
A8: IF-007 | B8: Biologie | C8: Basiskonzept Entwicklung | D8: Sexualität des Menschen | E8: S. 31 | F8: S. 31 | G8: S. 31
A9: IF-008 | B9: Biologie | C9: Basiskonzept Entwicklung | D9: Vielfalt, Veränderung und Abstammung von Lebewesen | E9: S. 32 | F9: S. 31 f. | G9: S. 31 f.
A10: IF-009 | B10: Chemie | C10: Struktur-Eigenschafts-Beziehungen; Stoff-Teilchen-Beziehungen | D10: Welt der Stoffe – Identifikation und Ordnung von Stoffen | E10: S. 22 | F10: S. 22 | G10: S. 22 f.
A11: IF-010 | B11: Chemie | C11: Struktur-Eigenschafts-Beziehungen; Stoff-Teilchen-Beziehungen | D11: Der Mix macht's – Stoffgemische | E11: S. 23 | F11: S. 23 | G11: S. 23 f.
A12: IF-011 | B12: Chemie | C12: Struktur-Eigenschafts-Beziehungen; Chemische Reaktion; Energetische Betrachtungen | D12: Verwandlungen – Chemische Reaktion | E12: S. 24 | F12: S. 24 | G12: S. 24 f.
A13: IF-012 | B13: Chemie | C13: Struktur-Eigenschafts-Beziehungen; Stoff-Teilchen-Beziehungen; Chemische Reaktion | D13: Tafel des Wissens – Periodensystem der Elemente | E13: S. 24 | F13: S. 24 | G13: S. 25
... A47: IF-046 | B47: Geschichte | C47: Geschichtswissenschaftliche Dimensionen | D47: Bewältigung und Nutzung von Räumen | E47: S. 24 | F47: S. 24 | G47: S. 24
A48: IF-047 | B48: Arbeitslehre | D48: Berufswegeplanung | E48: S. 20 | F48: S. 20 | H48: Kein Gymnasial-KC
A49: IF-048 | B49: Arbeitslehre | D49: Technische Systeme und Prozesse | E49: S. 20 | F49: S. 20
A50: IF-049 | B50: Arbeitslehre | D50: Organisation von Arbeit | E50: S. 21 | F50: S. 21
A51: IF-050 | B51: Arbeitslehre | D51: Ökonomisch geprägte Situationen und Strukturen des Zusammenlebens | E51: S. 21 | F51: S. 21
A52: IF-051 | B52: Arbeitslehre | D52: Erhalt der psychischen und physischen Gesundheit | E52: S. 21 | F52: S. 21
A53: IF-052 | B53: Arbeitslehre | D53: Zukunft der Arbeit | E53: S. 21 | F53: S. 21
A54: IF-053 | B54: Deutsch | D54: Rede- und Gesprächsformen | E54: S. 22 | F54: S. 22 | G54: S. 22
A55: IF-054 | B55: Deutsch | D55: Rede- und Gesprächsstrategien | E55: S. 22 | F55: S. 22 | G55: S. 22
A56: IF-055 | B56: Deutsch | D56: Rede- und Gesprächskonventionen | E56: S. 23 | F56: S. 23 | G56: S. 23
A57: IF-056 | B57: Deutsch | D57: Schreibformen | E57: S. 23 | F57: S. 23 | G57: S. 23
A58: IF-057 | B58: Deutsch | D58: Schreibstrategien | E58: S. 23 | F58: S. 23 | G58: S. 23
A59: IF-058 | B59: Deutsch | D59: Schreibnormen | E59: S. 24 | F59: S. 24 | G59: S. 24
A60: IF-059 | B60: Deutsch | D60: Text-/Medienformen | E60: S. 24 | F60: S. 24 | G60: S. 24
A61: IF-060 | B61: Deutsch | D61: Lese- und Rezeptionsstrategien | E61: S. 24 | F61: S. 24 | G61: S. 24
A62: IF-061 | B62: Deutsch | D62: Lesarten und Rezeptionskonventionen | E62: S. 25 | F62: S. 25 | G62: S. 25
A63: IF-062 | B63: Deutsch | D63: Sprachformen und -strukturen | E63: S. 25 | F63: S. 25 | G63: S. 25
A64: IF-063 | B64: Deutsch | D64: Analyseverfahren | E64: S. 26 | F64: S. 26 | G64: S. 26
A65: IF-064 | B65: Deutsch | D65: Sprachnormen | E65: S. 26 | F65: S. 26 | G65: S. 26
A66: IF-065 | B66: Mathematik | C66: Leitidee Zahl und Operation | D66: Zahlen | E66: S. 18 | F66: S. 18 | G66: S. 18
A67: IF-066 | B67: Mathematik | C67: Leitidee Zahl und Operation | D67: Operationen und ihre Eigenschaften | E67: S. 19 | F67: S. 19 | G67: S. 19
A68: IF-067 | B68: Mathematik | C68: Leitidee Raum und Form | D68: Ebene Figuren | E68: S. 19 | F68: S. 19 | G68: S. 19
A69: IF-068 | B69: Mathematik | C69: Leitidee Raum und Form | D69: Körper | E69: S. 19 | F69: S. 19 | G69: S. 19
A70: IF-069 | B70: Mathematik | C70: Leitidee Raum und Form | D70: Beziehungen zwischen geometrischen Objekten | E70: S. 19 | F70: S. 19 | G70: S. 19
A71: IF-070 | B71: Mathematik | C71: Leitidee Größen und Messen | D71: Umgang mit Größen | E71: S. 19 | F71: S. 20 | G71: S. 20
A72: IF-071 | B72: Mathematik | C72: Leitidee Größen und Messen | D72: Messvorgänge | E72: S. 20 | F72: S. 20 | G72: S. 20
A73: IF-072 | B73: Mathematik | C73: Leitidee Funktionaler Zusammenhang | D73: Darstellungen | E73: S. 20 | F73: S. 20 | G73: S. 20
...

Sheet Schwerpunkte
A1: ID | B1: Fach | C1: Inhaltsfeld | D1: KC-Fassung | E1: Stufe laut KC | F1: Inhaltlicher Schwerpunkt | G1: Seite
A2: SP-001 | B2: Biologie | C2: Biologische Strukturen und ihre Funktion | D2: Gymnasium | E2: bis Ende 5/6 | F2: Bau und Funktion von Organen und Organsystemen von Wirbeltieren oder dem Menschen | G2: S. 41
A3: SP-002 | B3: Biologie | C3: Biologische Strukturen und ihre Funktion | D3: Gymnasium | E3: bis Ende 5/6 | F3: Körperformen ausgewählter Organismen und deren Bedeutung für die Lebensweise | G3: S. 41
A4: SP-003 | B4: Biologie | C4: Biologische Strukturen und ihre Funktion | D4: Gymnasium | E4: bis Ende 5/6 | F4: Prinzip der Oberflächenvergrößerung anhand von Lunge oder Darm | G4: S. 41
A5: SP-004 | B5: Biologie | C5: Biologische Strukturen und ihre Funktion | D5: Gymnasium | E5: bis Ende 5/6 | F5: Gegenspielerprinzip am Beispiel der Skelettmuskulatur | G5: S. 41
A6: SP-005 | B6: Biologie | C6: Biologische Strukturen und ihre Funktion | D6: Gymnasium | E6: zusätzlich bis Ende 9/10 | F6: Weitergabe genetischer Informationen | G6: S. 41
A7: SP-006 | B7: Biologie | C7: Biologische Strukturen und ihre Funktion | D7: Gymnasium | E7: zusätzlich bis Ende 9/10 | F7: Strukturen und Funktionen auf makroskopischer Ebene (Organe, Organsysteme) | G7: S. 41
A8: SP-007 | B8: Biologie | C8: Biologische Strukturen und ihre Funktion | D8: Gymnasium | E8: zusätzlich bis Ende 9/10 | F8: Strukturen und Funktionen auf mikroskopischer Ebene (Zellaufbau ausgewählter Zellen) | G8: S. 41
A9: SP-008 | B9: Biologie | C9: Biologische Strukturen und ihre Funktion | D9: Gymnasium | E9: zusätzlich bis Ende 9/10 | F9: Schlüssel-Schloss-Prinzip, Oberflächenvergrößerung (auch zellulär), Gegenspielerprinzip | G9: S. 41
A10: SP-009 | B10: Biologie | C10: Informationsfluss im Organismus und zwischen Organismen | D10: Gymnasium | E10: bis Ende 5/6 | F10: Informationswege im Organismus auf phänomenologischer Ebene | G10: S. 42
A11: SP-010 | B11: Biologie | C11: Informationsfluss im Organismus und zwischen Organismen | D11: Gymnasium | E11: bis Ende 5/6 | F11: Einfache Beispiele für Verhaltensweisen aus der Tierwelt | G11: S. 42
A12: SP-011 | B12: Biologie | C12: Informationsfluss im Organismus und zwischen Organismen | D12: Gymnasium | E12: zusätzlich bis Ende 9/10 | F12: Verhaltensweisen von Tieren (intra- und interspezifisch) und des Menschen (soziale Verhaltensweisen, Sexualverhalten) | G12: S. 42
... A167: SP-166 | B167: Politik und Wirtschaft | C167: Internationale Beziehungen und Globalisierung | D167: Gymnasium | E167: keine Stufung im KC (gilt bis Ende 9/10) | F167: Migration und Integration | G167: S. 27

Sheet Kompetenzbereiche
A1: Fach | B1: Kompetenzbereich | C1: Teilbereiche / Operatoren | D1: Seite | E1: Hinweis
A2: Biologie | B2: Erkenntnisgewinnung | C2: Beobachten, beschreiben, vergleichen; Planen, untersuchen, auswerten, interpretieren; Arbeiten mit Modellen | D2: S. 14 | E2: In Biologie, Chemie und Physik einheitlich definiert
A3: Biologie | B3: Kommunikation | C3: Arbeiten mit Quellen; Kommunizieren, argumentieren; Dokumentieren, präsentieren; Verwenden von Fach- und Symbolsprache | D3: S. 14 | E3: In Biologie, Chemie und Physik einheitlich definiert
A4: Biologie | B4: Bewertung | C4: Beurteilen von Alltagskontexten mit naturwissenschaftlichen Kenntnissen; Abwägen und bewerten von Handlungsfolgen auf Natur und Gesellschaft; Reflektieren und bewerten von Handlungsoptionen als Grundlage gesellschaftlicher Partizipation | D4: S. 14 | E4: In Biologie, Chemie und Physik einheitlich definiert
A5: Biologie | B5: Nutzung fachlicher Konzepte | C5: Konzeptbezogenes Strukturieren von Sachverhalten; Vernetzen von Sachverhalten und Konzepten; Problemorientiertes und konzeptbezogenes Erschließen von Sachverhalten | D5: S. 14 | E5: In Biologie, Chemie und Physik einheitlich definiert
A6: Chemie | B6: Erkenntnisgewinnung | C6: Beobachten, beschreiben, vergleichen; Planen, untersuchen, auswerten, interpretieren; Arbeiten mit Modellen | D6: S. 13 | E6: In Biologie, Chemie und Physik einheitlich definiert
A7: Chemie | B7: Kommunikation | C7: Arbeiten mit Quellen; Kommunizieren, argumentieren; Dokumentieren, präsentieren; Verwenden von Fach- und Symbolsprache | D7: S. 13 | E7: In Biologie, Chemie und Physik einheitlich definiert
A8: Chemie | B8: Bewertung | C8: Beurteilen von Alltagskontexten mit naturwissenschaftlichen Kenntnissen; Abwägen und bewerten von Handlungsfolgen auf Natur und Gesellschaft; Reflektieren und bewerten von Handlungsoptionen als Grundlage gesellschaftlicher Partizipation | D8: S. 13 | E8: In Biologie, Chemie und Physik einheitlich definiert
A9: Chemie | B9: Nutzung fachlicher Konzepte | C9: Konzeptbezogenes Strukturieren von Sachverhalten; Vernetzen von Sachverhalten und Konzepten; Problemorientiertes und konzeptbezogenes Erschließen von Sachverhalten | D9: S. 13 | E9: In Biologie, Chemie und Physik einheitlich definiert
A10: Physik | B10: Erkenntnisgewinnung | C10: Beobachten, beschreiben, vergleichen; Planen, untersuchen, auswerten, interpretieren; Arbeiten mit Modellen | D10: S. 13 | E10: In Biologie, Chemie und Physik einheitlich definiert
A11: Physik | B11: Kommunikation | C11: Arbeiten mit Quellen; Kommunizieren, argumentieren; Dokumentieren, präsentieren; Verwenden von Fach- und Symbolsprache | D11: S. 13 | E11: In Biologie, Chemie und Physik einheitlich definiert
A12: Physik | B12: Bewertung | C12: Beurteilen von Alltagskontexten mit naturwissenschaftlichen Kenntnissen; Abwägen und bewerten von Handlungsfolgen auf Natur und Gesellschaft; Reflektieren und bewerten von Handlungsoptionen als Grundlage gesellschaftlicher Partizipation | D12: S. 13 | E12: In Biologie, Chemie und Physik einheitlich definiert
... A14: Erdkunde | B14: Geographische Analysekompetenz | C14: Umwelt-Gesellschaft-Beziehungen sowie natur- und humangeographische Systeme untersuchen | D14: S. 15 | E14: Übergeordnet: raumbezogene Handlungskompetenz
A15: Erdkunde | B15: Räumliche Orientierungskompetenz | C15: Orientierungswissen, Orientierungsraster und Ordnungssysteme nutzen; Karten lesen und auswerten; Raumwahrnehmung reflektieren | D15: S. 15
A16: Erdkunde | B16: Geographische Methodenkompetenz | C16: Geographisch relevante Informationsquellen und Methoden nutzen und reflektieren | D16: S. 16
A17: Erdkunde | B17: Geographische Urteils- und Kommunikationskompetenz | C17: Sachverhalte beurteilen und begründet bewerten; sach- und adressatengerecht kommunizieren | D17: S. 16
A18: Politik und Wirtschaft | B18: Analysekompetenz | C18: fragen, unterscheiden, beschreiben, strukturieren | D18: S. 18
A19: Politik und Wirtschaft | B19: Urteilskompetenz | C19: überprüfen, schlussfolgern, bewerten, entscheiden | D19: S. 18
A20: Politik und Wirtschaft | B20: Handlungskompetenz | C20: formulieren, vertreten, sich beteiligen, umsetzen | D20: S. 18
A21: Politik und Wirtschaft | B21: Methodenkompetenz | C21: entwickeln, forschen, aufbereiten, präsentieren | D21: S. 18

Sheet Querbezüge belegt
A1: Fach (Quelle) | B1: Bezug zu | C1: Aussage im KC (sinngemäß) | D1: Fundstelle
A2: alle fünf | B2: alle Fächer | C2: Teil A: Kompetenzbereiche und Inhaltsfelder sollen auch über die Fächergrenzen hinaus vernetzt werden | D2: Kap. 1, S. 7
A3: Biologie, Chemie, Physik | B3: untereinander | C3: Kompetenzbereiche der drei Naturwissenschaften sind einheitlich definiert und in Teilbereiche gegliedert | D3: Kap. 3 (Bio S. 13 f., Ch S. 12 f., Ph S. 12 f.)
A4: Physik | B4: Erdkunde | C4: Bei den zentralen Konzepten der PISA-Studie (u. a. System Erde und Weltraum) bietet sich eine Zusammenarbeit mit Erdkunde an | D4: Kap. 3, S. 12
A5: Physik | B5: Biologie, Chemie | C5: Das Basiskonzept Energie findet sich auch in den Fächern Biologie und Chemie wieder | D5: Kap. 5, S. 18
A6: Physik | B6: Biologie, Chemie | C6: Inhaltlicher Schwerpunkt 'Besonderheiten und Gemeinsamkeiten der Physik, Chemie und Biologie' (Haus der Naturwissenschaften) | D6: Kap. 7.2, S. 29
A7: Biologie | B7: Sozial- und Geisteswissenschaften, Naturwissenschaften | C7: Anknüpfungspunkte zu Sozial- und Geisteswissenschaften sowie den weiteren Naturwissenschaften | D7: Kap. 3, S. 11
A8: Biologie | B8: sozial- und geisteswissenschaftliche Fächer | C8: Gesundheits-, Sexual- und Umwelterziehung sowie Bioethik; ergänzende Konzepte und Arbeitsweisen aus sozial- und geisteswissenschaftlichen Fächern | D8: Kap. 4, S. 19
A9: Biologie | B9: andere Fächer, Einrichtungen | C9: Sexualität des Menschen (5/6): Zusammenarbeit mit anderen Fächern oder Einrichtungen | D9: Kap. 7.1, S. 38; Kap. 7.3, S. 46
A10: Chemie | B10: andere Fächer | C10: Schnittstellen u. a.: Gesellschaftsrelevanz und Umweltbewusstsein, moralisches Empfinden, Teamfähigkeit, ästhetisches Empfinden, kreatives Gestalten, Formulierungsfähigkeit, räumliches Vorstellungsvermögen, Gesundheitsbewusstsein und Ernährung | D10: Kap. 4, S. 16
A11: Erdkunde | B11: Geschichte, Politik und Wirtschaft | C11: Gemeinsames gesellschaftswissenschaftliches Aufgabenfeld; Perspektiven Raum (Erdkunde), Zeit (Geschichte), Entscheidung und Gestaltung (PoWi); Themenkoordination und zeitweilig fachübergreifender Unterricht; Lernbereich Gesellschaftslehre möglich | D11: Kap. 3, S. 12 f.
A12: Politik und Wirtschaft | B12: Erdkunde, Geschichte | C12: Gleicher Text wie bei Erdkunde; Abb. 1 zeigt Beispiele für Verzahnungen von Inhaltsfeldern (nur Grafik, nicht als Text auslesbar) | D12: Kap. 3, S. 13 f.
... A14: Politik und Wirtschaft | B14: Geschichte | C14: Handlungskompetenz: undemokratisches Verhalten erkennen und ein historisches Beispiel damit in Verbindung bringen | D14: Kap. 6, S. 23

Sheet Anknüpfungspunkte
A1: Thema | B1: Fach | C1: Inhaltsfeld | D1: Stichwort aus dem KC | E1: Stufe laut KC | F1: Status
A2: Energie | B2: Physik | C2: Energie in Umwelt und Technik | D2: Anschaulicher Energiebegriff; Energieformen und ihre Umwandlung | E2: nach ca. Hälfte des Stundenkontingents / zusätzlich bis Ende 9/10 | F2: Vorschlag, fachlich zu prüfen
A3: Energie | B3: Physik | C3: Zukunftssichere Energieversorgung | D3: Regenerative und erschöpfbare Energien | E3: nach ca. Hälfte des Stundenkontingents | F3: Vorschlag, fachlich zu prüfen
A4: Energie | B4: Chemie | C4: Verwandlungen – Chemische Reaktion | D4: Endotherme und exotherme Reaktionen | E4: 1. Lernjahr | F4: Vorschlag, fachlich zu prüfen
A5: Energie | B5: Biologie | C5: Stoffwechsel und Regelmechanismen | D5: Zusammenhänge zwischen Stoff- und Energieumwandlungen | E5: bis Ende 5/6 | F5: Vorschlag, fachlich zu prüfen
A6: Energie | B6: Erdkunde | C6: Umwelt-Gesellschaft-Beziehungen und globale Probleme | D6: Ressourcensicherung | E6: keine Stufung im KC (gilt bis Ende 9/10) | F6: Vorschlag, fachlich zu prüfen
A7: Energie | B7: Politik und Wirtschaft | C7: Gesellschaft und Natur | D7: Spannungsfeld zwischen Ökonomie und Ökologie | E7: keine Stufung im KC (gilt bis Ende 9/10) | F7: Vorschlag, fachlich zu prüfen
A8: Klima und Wetter | B8: Physik | C8: Wettererscheinungen und Klima | D8: Einfluss des Menschen auf das Klima und Folgen | E8: zusätzlich bis Ende 9/10 | F8: Vorschlag, fachlich zu prüfen
A9: Klima und Wetter | B9: Erdkunde | C9: Natur/Umwelt | D9: Geofaktor Klima | E9: keine Stufung im KC (gilt bis Ende 9/10) | F9: Vorschlag, fachlich zu prüfen
A10: Klima und Wetter | B10: Biologie | C10: Stoffwechsel und Regelmechanismen | D10: Stoffkreisläufe (z. B. Kohlenstoffkreislauf) | E10: zusätzlich bis Ende 9/10 | F10: Vorschlag, fachlich zu prüfen
A11: Klima und Wetter | B11: Politik und Wirtschaft | C11: Gesellschaft und Natur | D11: Nachhaltige Entwicklung, Generationenverantwortung | E11: keine Stufung im KC (gilt bis Ende 9/10) | F11: Vorschlag, fachlich zu prüfen
A12: Wasser, Luft, Boden, Stoffkreisläufe | B12: Chemie | C12: Schatzkiste der Natur – Chemie in Alltag und Technik | D12: Luft, Wasser, Boden; Stoffkreisläufe in Natur und Technik | E12: zusätzlich bis Ende 9/10 | F12: Vorschlag, fachlich zu prüfen
... A48: Technik, Forschung und Verantwortung | B48: Chemie | C48: Verwandlungen – Chemische Reaktion | D48: Chancen und Grenzen bei der Herstellung von Stoffen (Bewertung, Kap. 6, S. 24) | E48: Inhaltsfeldbeschreibung | F48: Vorschlag, fachlich zu prüfen

Sheet BNE Belege
A1: Fach | B1: Inhaltsfeld | C1: Seite HS | D1: Seite RS | E1: Seite GY | F1: Aussage im KC (gekürzt)
A2: Biologie | B2: Stoffwechsel und Regelmechanismen | C2: S. 30 | D2: S. 30 | E2: S. 30 | F2: Eingriffe des Menschen in ökologische Beziehungen; daraus Handlungsoptionen „im Sinne der Nachhaltigkeit“
A3: Biologie | B3: Wechselwirkungen in Ökosystemen | C3: S. 44 | D3: S. 44 | E3: S. 44 | F3: Bewertung: Beurteilung von Verhaltensweisen „hinsichtlich der Nachhaltigkeit“ (Kap. 7.3)
A4: Erdkunde | B4: Umwelt-Gesellschaft-Beziehungen und globale Probleme | C4: S. 24 | D4: S. 24 | E4: S. 24 | F4: „Prinzipien der Nachhaltigkeit“ werden in der Betrachtung berücksichtigt
A5: Physik | B5: Zukunftssichere Energieversorgung | C5: S. 26 | D5: S. 26 | E5: S. 26 | F5: „sichere und nachhaltige Energieversorgung“
A6: Politik und Wirtschaft | B6: Gesellschaft und Natur | C6: S. 26 | D6: S. 26 | E6: S. 26 | F6: Spannungsfeld zwischen Ökonomie und Ökologie; „Nachhaltige Entwicklung“
A7: Arbeitslehre | B7: Organisation von Arbeit | C7: S. 21 | D7: S. 21 | F7: Menschenwürdige Arbeitsbedingungen; u. a. „Umweltschutz und Nachhaltigkeit“
A8: Arbeitslehre | B8: Zukunft der Arbeit | C8: S. 21 | D8: S. 21 | F8: „Perspektiven einer nachhaltigen“ Unternehmensentwicklung
A9: Biologie | B9: (fachweiter Bildungsstandard) | C9: S. 26 | D9: S. 26 | E9: S. 27 | F9: Bildungsstandard Bewertung: Alternativen einer umwelt- und naturverträglichen Lebensweise „im Sinne der Nachhaltigkeit“ erörtern
A10: Chemie | B10: (fachweiter Bildungsstandard) | C10: S. 21 | D10: S. 21 | E10: S. 21 | F10: Bildungsstandard Bewertung: Alternativen einer umwelt- und naturverträglichen Lebensweise „im Sinne der Nachhaltigkeit“ erörtern
A11: Physik | B11: (fachweiter Bildungsstandard) | C11: S. 21 | D11: S. 21 | E11: S. 21 | F11: Bildungsstandard Bewertung: Alternativen einer umwelt- und naturverträglichen Lebensweise „im Sinne der Nachhaltigkeit“ erörtern
A12: Politik und Wirtschaft | B12: (fachweiter Bildungsstandard) | C12: S. 23 | D12: S. 23 | E12: S. 24 | F12: Bildungsstandard: Konsumentenentscheidungen „auch im Sinne von Nachhaltigkeit“ begründet treffen

Sheet SDG-Vorschläge
A1: SDG | B1: Nachhaltigkeitsziel | C1: Fach | D1: Inhaltsfeld | E1: Stichwort | F1: Status
A2: 1 | B2: Keine Armut | C2: Politik und Wirtschaft | D2: Wirtschaft | E2: Einkommen und Verteilung | F2: Vorschlag, fachlich zu prüfen
A3: 1 | B3: Keine Armut | C3: Politik und Wirtschaft | D3: Internationale Beziehungen und Globalisierung | E3: Globale Entwicklungsunterschiede | F3: Vorschlag, fachlich zu prüfen
A4: 1 | B4: Keine Armut | C4: Erdkunde | D4: Mensch/Gesellschaft | E4: Lebensbedingungen in verschiedenen Räumen | F4: Vorschlag, fachlich zu prüfen
A5: 1 | B5: Keine Armut | C5: Geschichte | D5: Epochenbezug Neuzeit | E5: Industrielle Revolutionen und Soziale Frage | F5: Vorschlag, fachlich zu prüfen
A6: 1 | B6: Keine Armut | C6: Arbeitslehre | D6: Ökonomisch geprägte Situationen und Strukturen des Zusammenlebens | E6: Einkommen und soziale Sicherung | F6: Vorschlag, fachlich zu prüfen
A7: 2 | B7: Kein Hunger | C7: Biologie | D7: Stoffwechsel und Regelmechanismen | E7: Ausgewogene Ernährung | F7: Vorschlag, fachlich zu prüfen
A8: 2 | B8: Kein Hunger | C8: Erdkunde | D8: Umwelt-Gesellschaft-Beziehungen und globale Probleme | E8: Ressourcensicherung | F8: Vorschlag, fachlich zu prüfen
A9: 3 | B9: Gesundheit und Wohlergehen | C9: Biologie | D9: Funktionsteilung im Organismus | E9: Immunsystem und Infektionskrankheiten | F9: Vorschlag, fachlich zu prüfen
A10: 3 | B10: Gesundheit und Wohlergehen | C10: Biologie | D10: Sexualität des Menschen | E10: Gesundheitserziehung | F10: Vorschlag, fachlich zu prüfen
A11: 3 | B11: Gesundheit und Wohlergehen | C11: Sport | D11: Den Körper trainieren, die Fitness verbessern | E11: Fitness und Gesundheit | F11: Vorschlag, fachlich zu prüfen
A12: 3 | B12: Gesundheit und Wohlergehen | C12: Arbeitslehre | D12: Erhalt der psychischen und physischen Gesundheit | E12: Gesundheit im Arbeitsleben | F12: Vorschlag, fachlich zu prüfen
A13: 4 | B13: Hochwertige Bildung | C13: Arbeitslehre | D13: Berufswegeplanung | E13: Bildungs- und Berufswege | F13: Vorschlag, fachlich zu prüfen
... A65: 17 | B65: Partnerschaften zur Erreichung der Ziele | C65: Katholische Religion | D65: Religionen | E65: Dialog der Religionen | F65: Vorschlag, fachlich zu prüfen

Sheet Hinweise und Lücken
A1: Punkt | B1: Hinweis
A2: Bildungsgang | B2: Inhaltsfelder sind für 17 Fächer in allen drei KC-Fassungen erfasst (Hauptschule, Realschule, Gymnasium). Schwerpunkte, Kompetenzbereiche und Querbezüge gibt es bisher nur für die fünf Pilotfächer in der Gymnasialfassung.
A3: Fächerauswahl | B3: Aufgenommen sind die Fächer einer IGS 5 bis 10. Latein, Griechisch, Chinesisch, Arabisch sowie alevitische, jüdische und islamische Religion fehlen noch. Informatik gibt es nur als KC für den Wahlunterricht am Gymnasium.
A4: Moderne Fremdsprachen | B4: Ein gemeinsames KC für alle modernen Fremdsprachen. Die Inhaltsfelder sind drei Lebenswelten.
A5: Kunst | B5: Die Zuordnung der neun Inhaltsfelder zu den drei Kernbereichen steht nur in Abb. 2 (Kap. 5).
A6: Religion | B6: Evangelische und Katholische Religion liegen in der neuen KC-Fassung von 2026 vor.
A7: BNE | B7: BNE ist nach § 6 Abs. 4 HSchG ein Aufgabengebiet. Die KC von 2011 nennen BNE nicht ausdrücklich. Als Beleg zählt nur, wo das KC selbst Nachhaltigkeit nennt (Blatt 'BNE Belege'). Die SDG-Zuordnung ist ein Vorschlag.
A8: Stufung | B8: Die Stufen sind nicht einheitlich: Biologie 'bis Ende 5/6', Chemie '1. Lernjahr', Physik 'nach ca. der Hälfte des Stundenkontingents', jeweils plus 'bis Ende 9/10'. Erdkunde und Politik und Wirtschaft haben im Gymnasium-KC keine Stufung. Die Zuordnung zu Jahrgängen hängt an der Stundentafel bzw. am Schulcurriculum.
A9: Jahrgang 8 | B9: Biologie, Chemie, Physik, Erdkunde und PoWi weisen für das Gymnasium ausdrücklich keine Kompetenzerwartungen für Jahrgang 6/8 bzw. 8 aus (jeweils Kap. 7).
A10: Erdkunde, PoWi | B10: Die Einträge im Blatt 'Schwerpunkte' sind Stichworte aus den Inhaltsfeldbeschreibungen (Kap. 6), da es keine Schwerpunkt-Tabelle gibt.
A11: PoWi | B11: Im PDF ist der rechte Teil der quer gesetzten Tabellen beim Auslesen abgeschnitten. Stichworte bitte am Original prüfen.
A12: Grafiken | B12: Abbildungen (z. B. Basiskonzept-Zuordnung Physik, Verzahnung Erdkunde/PoWi/Geschichte) ließen sich nicht als Text auslesen und fehlen.
... A14: Anknüpfungspunkte | B14: Das Blatt 'Anknüpfungspunkte' enthält Vorschläge auf Basis gemeinsamer Stichworte. Sie stehen so nicht im KC und sind fachlich zu prüfen.
